<?xml version="1.0"?>
<robot xmlns:xacro="http://www.ros.org/wiki/xacro">

    <xacro:include filename="inertial_macros.xacro"/>
    <xacro:include filename="$(find robot_simulation)/urdf/gazebo_control.gazebo"/>

    <material name="white">
        <color rgba="1 1 1 1" />
    </material>

    <material name="orange">
        <color rgba="1 0.3 0.1 1"/>
    </material>

    <material name="blue">
        <color rgba="0.2 0.2 1 1"/>
    </material>

    <material name="black">
        <color rgba="0 0 0 1"/>
    </material>

    <material name="red">
        <color rgba="1.0 0.0 0.0 1.0"/>
    </material>

    <!-- BASE LINK -->

    <link name="base_link">

    </link>


    <!-- CHASSIS LINK -->

    <joint name="chassis_joint" type="fixed">
        <parent link="base_link"/>
        <child link="chassis"/>
        <origin xyz="-0.1 0 0"/>
    </joint>

    <link name="chassis">
        <visual>
            <origin xyz="0.15 0 0.075"/>
            <geometry>
                <box size="0.3 0.3 0.15"/>
            </geometry>
            <material name="white"/>
        </visual>
        <collision>
            <origin xyz="0.15 0 0.075"/>
            <geometry>
                <box size="0.3 0.3 0.15"/>
            </geometry>
        </collision>
        <xacro:inertial_box mass="0.5" x="0.3" y="0.3" z="0.15">
            <origin xyz="0.15 0 0.075" rpy="0 0 0"/>
        </xacro:inertial_box>
    </link>

    <!-- <! LEFT WHEEL LINK -->

    <link name="left_wheel">
        <visual>
            <geometry>
                <cylinder radius="0.05" length="0.04"/>
            </geometry>
            <material name="blue"/>
        </visual>
        <collision>
            <geometry>
                <cylinder radius="0.05" length="0.04"/>
            </geometry>
        </collision>
        <xacro:inertial_cylinder mass="0.1" length="0.04" radius="0.05">
            <origin xyz="0 0 0" rpy="0 0 0"/>
        </xacro:inertial_cylinder>
    </link>

    <joint name="left_wheel_joint" type="continuous">
        <parent link="base_link"/>
        <child link="left_wheel"/>
        <origin xyz="0 0.175 0" rpy="-${pi/2} 0 0" />
        <axis xyz="0 0 1"/>
    </joint>




    <!-- RIGHT WHEEL LINK -->


    <link name="right_wheel">
        <visual>
            <geometry>
                <cylinder radius="0.05" length="0.04"/>
            </geometry>
            <material name="blue"/>
        </visual>
        <collision>
            <geometry>
                <cylinder radius="0.05" length="0.04"/>
            </geometry>
        </collision>
        <xacro:inertial_cylinder mass="0.1" length="0.04" radius="0.05">
            <origin xyz="0 0 0" rpy="0 0 0"/>
        </xacro:inertial_cylinder>
    </link>

    <joint name="right_wheel_joint" type="continuous">
        <parent link="base_link"/>
        <child link="right_wheel"/>
        <origin xyz="0 -0.175 0" rpy="${pi/2} 0 0" />
        <axis xyz="0 0 -1"/>
    </joint>



    <!-- CASTER WHEEL LINK -->

    <link name="front_caster_wheel_link">
        <visual >
            <geometry>
                <box size="0.05 0.05 0.05"/>
            </geometry>
            <material name="red"/>
        </visual>
        <collision>
            <geometry>
                <box size="0.05 0.05 0.05"/>
            </geometry>
        </collision>
        <xacro:inertial_box mass="0.1" x="0.1" y="0.1" z="0.1">
            <origin xyz="0.0 0 0.0" rpy="0 0 0"/>
        </xacro:inertial_box>

    </link>

    <joint name="front_caster_wheel_joint" type="continuous">
        <axis xyz="0.0 0.0 1"/>
        <parent link="base_link"/>
        <child link="front_caster_wheel_link"/>
        <origin xyz="0.15 0.0 -0.005" rpy="0.0 0.0 0.0"/>
    </joint>


    <link name="front_wheel_link">
        <visual>
            <geometry>
                <cylinder radius="0.025" length="0.05"/>
            </geometry>
            <material name="black">

            </material>

        </visual>
        <collision>
            <geometry>
                <cylinder radius="0.025" length="0.05"/>
            </geometry>
        </collision>

        <xacro:inertial_cylinder mass="0.1" length="0.05" radius="0.025">
            <origin xyz="0 0 0" rpy="0 0 0"/>
        </xacro:inertial_cylinder>
    </link>

    <joint name="front_wheel_joint" type="continuous">
        <axis xyz="0.0 0.0 1"/>
        <parent link="front_caster_wheel_link"/>
        <child link="front_wheel_link"/>
        <origin xyz="0.025 0.0 -0.02" rpy="-1.5708 0.0 0.0"/>
    </joint>

    <!-- Create A lidar Link -->
    <link name="lidar_link">
        <visual>
            <geometry>
                <cylinder radius="0.06" length="0.06"/>
            </geometry>
            <material name="black">
            </material>

        </visual>
        <collision>
            <geometry>
                <cylinder radius="0.06" length="0.06"/>
            </geometry>
        </collision>

        <xacro:inertial_cylinder mass="0.15" length="0.3" radius="0.4">
            <origin xyz="0 0 0" rpy="0 0 0"/>
        </xacro:inertial_cylinder>
    </link>
    
    <joint name="lidar_joint" type="fixed">
        <axis xyz="0.0 0 1"/>
        <parent link="base_link"/>
        <child link="lidar_link"/>
        <origin xyz="0.0 0.0 0.18" rpy="0 0.0 0"/>
    </joint>

    <!-- create camera link -->
     <link name="camera_link">
        <visual>
            <geometry>
                <box size="0.1 0.02 0.028"/>
            </geometry>
            <material name="blue">
            </material>

        </visual>
        <collision>
            <geometry>
               <box size="0.1 0.02 0.028"/>
            </geometry>
        </collision>

        <xacro:inertial_box   mass="0.01" x="0.02" y="0.1" z="0.28">
            <origin xyz="0 0 0" rpy="0 0 0"/>
        </xacro:inertial_box>
    </link>
    
    <joint name="camera_joint" type="fixed">
        <axis xyz="0.0 0 1"/>
        <parent link="chassis"/>
        <child link="camera_link"/>
        <origin xyz="0.31 0.0 0.12" rpy="${-pi/2} 0.0 ${-pi/2}"/>
    </joint>

</robot>